Workbook

Sheet En plazo
A1: Nueva | B1: Fecha límite | C1: Días restantes | D1: Presupuesto base sin IVA | E1: Valor estimado | F1: Comunidad | G1: Provincia | H1: Municipio | I1: Órgano de contratación | J1: Objeto | K1: Expediente | L1: Procedimiento | M1: Plazo de ejecución (meses) | N1: Clasificación exigida | O1: Juicio de valor | P1: Criterios de adjudicación | Q1: Garantías | R1: Revisión de precios | S1: Nº lotes | T1: CPV | U1: PCAP | V1: PPT | W1: Ficha PLACSP | X1: Primera detección | Y1: Cambios
B2: 46321.375 | C2: =IF(B2="","",INT(B2)-TODAY()) | D2: 889866.1 | E2: 1067839.3 | F2: Comunitat Valenciana | G2: Alicante | H2: Alicante | I2: Mercados Centrales De Abastecimiento de Alicante S.A. | J2: Sustitución de las cubiertas de fibrocemento de la nave III de Mercalicante | K2: 21/2026EXPL | L2: Abierto simplificado | M2: 10 | O2: 0.25 | P2: Plan de obra 5 (JV) | Experiencia del jefe y del encargado de obra 10 | Ampliación del plazo de garantía 5 | Memoria y estudio de obra 20 (JV) | Oferta económica 54 | Mantenimiento de la cubierta y líneas de vida 6 | Q2: complementaria 5%; definitiva 5% | T2: 45000000; 45421160; 45261220; 45262660; 45261420 | U2: PCAP | V2: PPT | W2: Ver | X2: 46310
B3: 46321.542 | C3: =IF(B3="","",INT(B3)-TODAY()) | D3: 3837538.7 | E3: 4221292.6 | F3: Andalucía | G3: Sevilla | I3: Gerencia de Sevilla Activa SAU | J3: Terminación de 50 Viviendas Protegidas | K3: A41420191-2026/000082-PaA | L3: Abierto | M3: 12 | N3: C*-5; G*-5; G6-4; C4-4 | O3: 0.3 | P3: memoria técnica [1] 30 (JV) | ampliación del plazo de garantía de la obra sobre el mínimo de un año [3] 15 | visita guiada [2] 15 | Aspecto Económico (precio) [1] 40 | T3: 45211000 | U3: PCAP | V3: PPT | W3: Ver | X3: 46310
B4: 46321.583 | C4: =IF(B4="","",INT(B4)-TODAY()) | D4: 585223.15 | E4: 585223.15 | F4: Comunitat Valenciana | G4: Valencia | I4: Presidencia de la Entidad Valenciana de Vivienda y Suelo | J4: Obras de Reparación y Refuerzo Estructural e Intervenciones puntuales en Fachadas y Cubiertas, así como Obras de Reparación y Refuerzo Estructural e Intervenciones puntuales en el interior de los edificios de la Manzana D del Grupo de Viviendas de Promoción Pública 030001 Miguel Hernández de Alicante. | K4: CMAYOR/2026/EVHA0/0011 | L4: Abierto simplificado | M4: 4 | N4: C4-3; C*-4 | O4: 0.2 | P4: CALIDAD 20 (JV) | Oferta económica 80 | Q4: definitiva 5% | T4: 45200000 | U4: PCAP | V4: PPT | W4: Ver | X4: 46317
B5: 46321.583 | C5: =IF(B5="","",INT(B5)-TODAY()) | D5: 792000 | E5: 1742400 | F5: Comunitat Valenciana | G5: Valencia | I5: Presidencia de la Entidad Valenciana de Vivienda y Suelo | J5: Mantenimiento correctivo (incluyendo la gestión integral de reclamaciones) de los inmuebles que componen el patrimonio público de viviendas de la Generalitat en la provincia de Castellón para los ejercicios 2027/2028. | K5: CMAYOR/2026/EVHA0/0012 | L5: Abierto | M5: 24 | N5: I6-1; C4-2; J4-1; C9-2 | O5: 0.4 | P5: Seguridad y Salud 5 (JV) | Control de calidad 5 (JV) | Propuesta organizativa 10 (JV) | Oferta económica 60 | Propuesta metodológica 10 (JV) | Análisis Plazos estimados y Base de Precios 10 (JV) | Q5: definitiva 5% | T5: 45200000; 71000000 | U5: PCAP | W5: Ver | X5: 46317
B6: 46321.792 | C6: =IF(B6="","",INT(B6)-TODAY()) | D6: 1650496 | E6: 1650496 | F6: Andalucía | G6: Málaga | I6: Instituto de Turismo de España (TURESPAÑA) | J6: Contrato para la ejecución de obras de la Fase II de las obras para la protección y consolidación del frente de acantilado del parador de turismo de Nerja (Málaga) | K6: 020026C00098 | L6: Abierto simplificado | M6: 10 | O6: 0 | P6: OFERTA ECONÓMICA 65 | OTROS CRITERIOS CUANTIFICABLES AUTOMATICAMENTE 35 | Q6: complementaria 5%; definitiva 5% | T6: 45200000 | U6: PCAP | V6: PPT | W6: Ver | X6: 46310
B7: 46321.999 | C7: =IF(B7="","",INT(B7)-TODAY()) | D7: 636363.64 | E7: 636363.64 | F7: Andalucía | G7: Huelva | I7: Junta de Gobierno del Ayuntamiento de Almonte | J7: ejecución de obras del proyecto de ejecución para la rehabilitación energética del edificio "hacienda santa maría" -proyectos Miteco- derivadas de proyecto subvencionado por el ministerio para la transición ecológica y el reto demográfico en aplicación del Real decreto 842/2024, de 27 de agosto, | K7: 12054/2026 | L7: Abierto simplificado | M7: 10 | N7: C*-3 | O7: 0.25 | P7: Procedencia de materiales y proveedores 4 (JV) | Compromiso de reducción del plazo de ejecución de la obra 25 | Recursos: personal, maquinaria y medios auxiliares 7 (JV) | Mejoras sociales de inserción 10 | Propuesta Plan de Obra 5 (JV) | Organización de los trabajos 5 (JV) | Ampliación de garantía 10 | Mejoras ambientales y/o de accesibilidad 20 | Propuesta del Plan de Aseguramiento de la Calidad 4 (JV) | Medidas medioambientales 10 | Q7: definitiva 5% | T7: 45200000 | U7: PCAP | V7: PPT | W7: Ver | X7: 46310
B8: 46321.999 | C8: =IF(B8="","",INT(B8)-TODAY()) | D8: 1025843.2 | E8: 1025843.2 | F8: Andalucía | G8: Málaga | H8: Alhaurín el Grande | I8: Alcaldía del Ayuntamiento de Alhaurín el Grande | J8: Proyecto de obras de renaturalización de las Avenidas Blas Infante y Libertad. Tramo 4 | K8: 25734/2026 BLAS INFANTE Y LIBERTAD | L8: Abierto simplificado | M8: 14 | O8: 0.1 | P8: Proposición económica 80 | Memoria constructiva y programa de trabajo 4 (JV) | Medidas para reducir el impacto Ambiental 2 (JV) | Medidas para reducir el impacto urbano de la obra 4 (JV) | ampliación en el plazo de garantía 10 | Q8: definitiva 5% | T8: 45223210; 45262520; 45233140; 45262210; 45112000; 45232100 | U8: PCAP | V8: PPT | W8: Ver | X8: 46310
B9: 46321.999 | C9: =IF(B9="","",INT(B9)-TODAY()) | D9: 4198877.4 | E9: 4198877.4 | F9: Comunitat Valenciana | G9: Alicante | I9: Consejo de Administración de Promociones e Iniciativas Municipales de Elche, S.A. (PIMESA) | J9: Obras de Construcción de un Edificio de 45 viviendas protegidas (VPNC), local, sótano para 44 aparcamientos y urbanización interior en la calle Obispo Cubero, nº2, Parcela nº5 del PRIM, Barrio San Antón de Elche. | K9: 2026/A/003 | L9: Abierto | M9: 24 | N9: C*-4 | O9: 0.25 | P9: Criterios evaluables mediante juicio de valor. 25 (JV) | Criterio evaluable de forma automática. Otros criterios 15 | Criterios evaluables de forma automática. Oferta Económica 60 | Q9: definitiva 5% | T9: 45211340 | U9: PCAP | W9: Ver | X9: 46311
B10: 46321.999 | C10: =IF(B10="","",INT(B10)-TODAY()) | D10: 725142.59 | E10: 725142.59 | F10: Andalucía | G10: Almería | I10: Junta de Gobierno de la Diputación Provincial de Almería | J10: Consolidacióin Primaria Cortijo Del Fraile 1PGM2026 | K10: 2026/D31000/006-013/00029 | L10: Abierto simplificado | M10: 10 | O10: 0.25 | P10: Oferta Técnica 25 (JV) | Precio 75 | Q10: complementaria 5%; definitiva 5% | T10: 45212350 | U10: PCAP | V10: PPT | W10: Ver | X10: 46317
B11: 46322.999 | C11: =IF(B11="","",INT(B11)-TODAY()) | D11: 1408264.5 | E11: 1408264.5 | F11: Andalucía | G11: Almería | I11: Junta de Gobierno de la Diputación Provincial de Almería | J11: Obras De Urbanización Para Un Complejo Deportivo. Vera 72PPOS24-27BI | K11: 2026/D31000/006-013/00078 | L11: Abierto simplificado | M11: 12.2 | N11: G6-4 | O11: 0.25 | P11: Oferta técnica 25 (JV) | Precio 75 | Q11: definitiva 5%; complementaria 5% | T11: 45233200 | U11: PCAP | V11: PPT | W11: Ver | X11: 46310
B12: 46322.999 | C12: =IF(B12="","",INT(B12)-TODAY()) | D12: 826446.28 | E12: 826446.28 | F12: Andalucía | G12: Almería | I12: Junta de Gobierno de la Diputación Provincial de Almería | J12: Rehabilitación Y Mejora De Edificios Municipales. Benahadux 19PPOS24-27BII | K12: 2026/D31000/006-013/00009 | L12: Abierto simplificado | M12: 15 | N12: C6-3; C4-3 | O12: 0.25 | P12: Oferta Técnica 25 (JV) | Precio 75 | Q12: complementaria 5%; definitiva 5% | T12: 45214000 | U12: PCAP | V12: PPT | W12: Ver | X12: 46310
B13: 46323.041 | C13: =IF(B13="","",INT(B13)-TODAY()) | D13: 547041.28 | E13: 547041.28 | F13: Andalucía | G13: Sevilla | H13: Sevilla | I13: Consejo de Administración de la Agencia de Régimen Especial Ciclo Integral Aguas del Retortillo | J13: PAS/OBRAS/007/2026 Obras construcción EDAR Natural Puerto de la Encina | K13: 1009/2026 | L13: Abierto simplificado | M13: 6 | N13: E1-3 | O13: 0 | P13: Calidad: Ampliación Garantía 6 | Calidad. Experiencia Jefe de Obras 10 | PRECIO 84 | Q13: definitiva 5% | T13: 45252100 | U13: PCAP | V13: PPT | W13: Ver | X13: 46310
B14: 46323.5 | C14: =IF(B14="","",INT(B14)-TODAY()) | D14: 794991.59 | E14: 794991.59 | F14: Andalucía | G14: Málaga | H14: Málaga | I14: Aena. Dirección del Aeropuerto de Málaga-Costa del Sol | J14: Ampliación Y Adecuación De Aseo 208 En El Aeropuerto De Málaga ¿ Costa Del Sol | K14: AGP-147/2026 | L14: Normas internas | M14: 14 | O14: 0 | P14: Precio 100 | T14: 45211310 | U14: PCAP | V14: PPT | W14: Ver | X14: 46310
B15: 46323.5 | C15: =IF(B15="","",INT(B15)-TODAY()) | D15: 653963.23 | E15: 653963.23 | F15: Comunitat Valenciana | G15: Alicante | H15: Almoradí | I15: Junta de Gobierno del Ayuntamiento de Almoradí | J15: Mejora de la accesibilidad y la escena urbana en el entorno del Teatro Cortés y Museo del Terremoto (Plan de Actuación Integrado PAI, cofinanciado con la Unión Europea - FEDER) | K15: 6981/2026 | L15: Abierto simplificado | M15: 5 | O15: 0.25 | P15: Proposición económica 75 | Memoria Técnica 25 (JV) | Q15: complementaria 5%; definitiva 5% | T15: 45233200; 45000000; 45111100; 45233140; 45233253; 45211360 | U15: PCAP | W15: Ver | X15: 46310
B16: 46323.999 | C16: =IF(B16="","",INT(B16)-TODAY()) | D16: 734951.31 | E16: 734951.31 | F16: Comunitat Valenciana | G16: Valencia | I16: Alcaldía del Ayuntamiento de Manises | J16: Reasfaltado de la travesia de Manises de la CV-370 desde Avenida dels Tranvies hasta la V-11 de acceso al aeropuerto y sustitución del alumbrado del puente de la CV-371 en el término de Manises | K16: 3034000P | L16: Abierto simplificado | M16: 2 | N16: G4-3 | O16: 0 | P16: Oferta económica 70 | Amplliación del plazo de garantia 30 | T16: 45233222; 45233252; 45233223; 45233251; 34928530; 34991000; 50232100 | U16: PCAP | V16: PPT | W16: Ver | X16: 46310
B17: 46323.999 | C17: =IF(B17="","",INT(B17)-TODAY()) | D17: 812294 | E17: 812294 | F17: Comunitat Valenciana | G17: Valencia | H17: el Genovés | I17: Pleno del Ayuntamiento de Genovés | J17: Construcción de un edificio de nueva planta, destinado a la población joven de la localidad, emplazado en calle Maestro Serrano nº 4 de El Genovés. | K17: 2222/2026 | L17: Abierto simplificado | M17: 10 | N17: C*-3 | O17: 0 | P17: Mejor oferta económica 100 | Q17: definitiva 5% | T17: 45000000; 45220000; 45200000 | U17: PCAP | V17: PPT | W17: Ver | X17: 46310
B18: 46323.999 | C18: =IF(B18="","",INT(B18)-TODAY()) | D18: 675994.61 | E18: 743594.07 | F18: Comunitat Valenciana | G18: Valencia | I18: Junta de Gobierno del Ajuntament de València | J18: Ejecución de las Obras denominadas Limpieza y mantenimiento de las fachadas del Mercado Central de València.- | K18: 04101/2026/236-O | L18: Abierto simplificado | M18: 5 | N18: K7-3 | O18: 0 | P18: REDUCCIÓN DEL PLAZO DE EJECUCIÓN 20 | BAJA ECONÓMICA AL PRESUPUESTO BASE DE LICITACIÓN 40 | EXPERIENCIA PROFESIONAL ESPECÍFICA DE LAS PERSONAS INTEGRANTES DEL EQUIPO DE TRABAJO 30 | AMPLIACIÓN PLAZO DE GARANTIA 10 | Q18: definitiva 5% | T18: 45213141 | U18: PCAP | V18: PPT | W18: Ver | X18: 46310
B19: 46324.5 | C19: =IF(B19="","",INT(B19)-TODAY()) | D19: 20327127 | E19: 21140212 | F19: Andalucía | G19: Málaga | H19: Málaga | I19: Aena. Consejo de Administración | J19: Actuaciones En Pavimento En Rodadura A Y Salidas Asociadas. Aeropuerto De Málaga - Costa Del Sol. | K19: DIN-442/2026 | L19: Licitación con negociación | M19: 37 | O19: 0 | P19: Precio 100 | T19: 45235311 | U19: PCAP | V19: PPT | W19: Ver | X19: 46314
B20: 46324.583 | C20: =IF(B20="","",INT(B20)-TODAY()) | D20: 743801.65 | E20: 743801.65 | F20: Andalucía | G20: Sevilla | I20: Alcaldia del Ayuntamiento de Pilas | J20: Ejecución de la obra "Proyecto de reasfaltado 2026, de Pilas (Sevilla). | K20: P4107500C-2026/000082-PAAS | L20: Abierto simplificado | M20: 6 | N20: G4-3; G*-3 | O20: 0 | P20: Reducción del plazo de ejecución [2] 10 | Aspecto Económico (precio) [1] 75 | Mejoras [3] 15 | T20: 45233222 | U20: PCAP | V20: PPT | W20: Ver | X20: 46310
B21: 46324.625 | C21: =IF(B21="","",INT(B21)-TODAY()) | D21: 799446.19 | E21: 959335.43 | F21: Andalucía | G21: Málaga | H21: Torre de Benagalbón, término municipal de Rincón de la Victoria | I21: Alcaldía del Ayuntamiento de Rincón de la Victoria | J21: Aparcamientos en sótano del Pabellón Rubén Ruzafa | K21: Contratación 57/26 | L21: Abierto simplificado | M21: 8 | N21: C4-3 | O21: 0.25 | P21: Reducción del plazo de ejecución al estipulado en el PCAP 30 | Programa de los trabajos compatibilizando la ejecución de obra con el funcionamiento del Pabellón 10 (JV) | Memoria de desarrollo del proyecto, las obras y propuestas para la mejora de la eficiencia y calidad de los trabajos 15 (JV) | Oferta económica 30 | Ampliación del plazo de garantía a añadir al estipulado en el PCAP 15 | Q21: definitiva 5% | R21: No procede (Punto 6 del Anexo I) | T21: 45000000; 45223310 | U21: PCAP | V21: PPT | W21: Ver | X21: 46317 | Y21: 2026-10-23: plazo 2026-10-26 15:00 → 2026-10-29 15:00
B22: 46324.999 | C22: =IF(B22="","",INT(B22)-TODAY()) | D22: 667189.24 | E22: 667189.24 | F22: Andalucía | G22: Huelva | H22: ISLA CRISTINA | I22: Alcaldía del Ayuntamiento de Isla Cristina | J22: Obras Proyecto de renovación y mejora de la eficiencia energética de las instalaciones de alumbrado público exterior del municipio de Isla Cristina. | K22: 5773/2026 | L22: Abierto simplificado | M22: 6.1 | N22: I1-3 | O22: 0.25 | P22: Ampliación plazo garantía 10 | Calidad técnica de la propuesta de ejecución 25 (JV) | Oferta económica 60 | Primera intervención efectiva ante incidencias cubiertas por la garantía 5 | Q22: definitiva 5% | T22: 45316100; 45315600 | U22: PCAP | V22: PPT | W22: Ver | X22: 46310
B23: 46324.999 | C23: =IF(B23="","",INT(B23)-TODAY()) | D23: 568417.81 | E23: 568417.81 | F23: Andalucía | G23: Huelva | H23: BONARES | I23: Alcaldia del Ayuntamiento de Bonares | J23: Creación de aparcamiento y plaza pública ajardinada en Avda. Nuestra Señora del Rocío nº 3 de Bonares (Huelva | K23: 4654/2026 | L23: Abierto simplificado | M23: 12 | N23: C*-3 | O23: 0 | P23: REDUCCIÓN DEL PLAZO DE EJECUCIÓN 12 | OFERTA ECONÓMICA 68 | AUMENTO PLAZO DE GARANTÍA 20 | Q23: definitiva 5% | R23: No se prevé la revisión de precios (Cláusula 6.9. del PCAP). | T23: 45220000; 45223000; 45000000 | U23: PCAP | V23: PPT | W23: Ver | X23: 46310
B24: 46325.583 | C24: =IF(B24="","",INT(B24)-TODAY()) | D24: 1540129.7 | E24: 1540129.7 | F24: Andalucía | G24: Granada | H24: Granada | I24: Secretaría General de la Agencia Estatal Consejo Superior de Investigaciones Científicas | J24: Obras de nuevo edificio del Instituto de Astrofísica de Andalucía | K24: 35349/26 | L24: Abierto simplificado | M24: 12 | O24: 0.25 | P24: Documentación complementaria 4 (JV) | Características técnicas del control de calidad de la ejecución de la obra 3 (JV) | Plan de mantenimiento técnico-legal 15 | Estudio del proyecto 8 (JV) | Memoria de ejecución de las obras y análisis y programa de trabajos 10 (JV) | Porcentaje ofertado de control de calidad 8 | Ampliación del plazo de garantía 12 | Oferta economica 40 | T24: 45214000; 45214600; 45213150 | U24: PCAP | V24: PPT | W24: Ver | X24: 46310
B25: 46328.333 | C25: =IF(B25="","",INT(B25)-TODAY()) | D25: 1189873.9 | E25: 1189873.9 | F25: Comunitat Valenciana | G25: Alicante | H25: ORIHUELA | I25: Junta de Gobierno del Ayuntamiento de Orihuela | J25: Rehabilitación de Paramentos y Acondicionamiento de Sala de hombres en el Museo Arqueológico Comarcal de Orihuela | K25: 4727/2026 BIS | L25: Abierto simplificado | M25: 12 | N25: C*-3; K7-3 | O25: 0.25 | P25: Ampliación del plazo de garantía 30 | OFERTA ECONÓMICA (Sin IVA) 45 | Estudio de unidades de obra del proyecto 15 (JV) | Estudio de mediciones del proyecto 10 (JV) | Q25: complementaria 5%; definitiva 5% | T25: 45000000; 45454100; 45453000 | U25: PCAP | V25: PPT | W25: Ver | X25: 46310
B26: 46328.583 | C26: =IF(B26="","",INT(B26)-TODAY()) | D26: 557102.23 | E26: 557102.23 | F26: Comunitat Valenciana | G26: Valencia | H26: REQUENA | I26: Junta de Gobierno Local del Ayuntamiento de Requena | J26: Demolicion y construccion Centro Social de Campo Arcís | K26: 2896352M | L26: Abierto simplificado | M26: 24 | O26: 0 | P26: Mejora en el Precio, 100 puntos 100 | Q26: definitiva 5% | T26: 45211350; 45111100 | U26: PCAP | V26: PPT | W26: Ver | X26: 46310
B27: 46328.583 | C27: =IF(B27="","",INT(B27)-TODAY()) | D27: 814296.7 | E27: 814296.7 | F27: Comunitat Valenciana | G27: Valencia | H27: Turís | I27: Alcaldía del Ayuntamiento de Turis | J27: Urbanización calles perimetrales parcela nuevo CEIP | K27: 3385/2026 | L27: Abierto simplificado | M27: 5 | O27: 0 | P27: Precio 100 | Q27: definitiva 5% | T27: 45233140 | U27: PCAP | V27: PPT | W27: Ver | X27: 46310
B28: 46328.583 | C28: =IF(B28="","",INT(B28)-TODAY()) | D28: 40000000 | E28: 80000000 | F28: Andalucía | G28: Almería | I28: Empresa de Transformación Agraria S.A.,S.M.E., M.P., (TRAGSA) | J28: Conclusión del Acuerdo Marco Para La Contratación de Las Obras Alquiler De Maquinaria De Obra Civil, Agrícola y Forestal, y Camiones, Dotada de Operario, Para Las Actuaciones de La Gerencia Provincial de Tragsa en Almería, Incluidas Obras Financiadas Con Fondos Europeos | K28: TSA0084163 | L28: Abierto | M28: 24 | N28: D*-1; A*-1; K*-1; C*-1; G*-1; E*-1 | O28: 0 | P28: Precio de la oferta 100 | R28: No | T28: 45500000 | U28: PCAP | V28: PPT | W28: Ver | X28: 46314 | Y28: 2026-10-20: estado PRE → PUB
B29: 46328.999 | C29: =IF(B29="","",INT(B29)-TODAY()) | D29: 4502927.3 | E29: 4502927.3 | F29: Comunitat Valenciana | G29: Valencia | I29: Pleno del Ayuntamiento de Carlet | J29: Obras de restitución de las canalizaciones de la red de agua potable y de la red de saneamiento y pavimentación de la Ronda Malecón, financiadas con cargo al Fondo de Solidaridad de la Unión Europea | K29: 3018/2026 | L29: Abierto | M29: 12 | N29: E*-5 | O29: 0 | P29: Ampliación del plazo de garantía 10 | Uso de materiales con menor huella de carbono 20 | Reducción del plazo de ejecución 20 | Oferta económica 50 | Q29: definitiva 5% | T29: 45240000; 45233200; 45232150; 45232440 | U29: PCAP | V29: PPT | W29: Ver | X29: 46310
B30: 46329.458 | C30: =IF(B30="","",INT(B30)-TODAY()) | D30: 590000 | E30: 590000 | F30: Andalucía | G30: Cádiz | I30: Comité Central de Compras de Navantia S.A., S.M.E. | J30: Licitación para la adjudicación de un Contrato para los trabajos de rehabilitación de accesos, protecciones colectivas y líneas de vida en grúas en Navantia Cádiz. | K30: 5100075545 Líneas Vida Grúas Navantia Cádiz | L30: Normas internas | M30: 7 | O30: 1 | P30: Según PPT y PCP 100 (JV) | T30: 45262600; 45340000 | U30: PCAP | V30: PPT | W30: Ver | X30: 46310 | Y30: 2026-10-26: plazo 2026-10-28 12:00 → 2026-11-03 11:00
B31: 46329.5 | C31: =IF(B31="","",INT(B31)-TODAY()) | D31: 41658023 | E31: 43324344 | F31: Comunitat Valenciana | G31: Valencia | H31: Valencia / València | I31: Aena. Consejo de Administración | J31: Recrecido De Pista, Adecuación De Calles De Rodaje Y Mejora Del Camino Perimetral. Aeropuerto De Valencia | K31: DIN-350/2026 | L31: Licitación con negociación | M31: 27 | O31: 0 | P31: Precio 100 | T31: 45235000 | U31: PCAP | V31: PPT | W31: Ver | X31: 46317
B32: 46329.583 | C32: =IF(B32="","",INT(B32)-TODAY()) | D32: 988010.83 | E32: 988010.83 | F32: Andalucía | G32: Sevilla | H32: Gines | I32: Junta de Gobierno Local del Ayuntamiento de Gines | J32: Obras de rehabilitación y adecuación de inmueble municipal en plantas baja y sótano para aparcamiento público municipal y locales de usos culturales y sociales. | K32: 6859/2026 | L32: Abierto simplificado | M32: 6 | N32: C*-2 | O32: 0.25 | P32: AMPLIACIÓN DEL PLAZO DE GARANTÍA DE LAS OBRAS 10 | VALORACIÓN DE RESIDUOS DE CONSTRUCCIÓN Y DEMOLICIÓN 5 | MEJORA 2: SISTEMA DE MONITORIZACIÓN ENERGÉTICA 5 | MEMORIA TÉCNICA DE EJECUCIÓN DE LA OBRA 10 (JV) | OFERTA ECONÓMICA 45 | PLAN DE MINIMIZACIÓN DE AFECCIONES AL ENTORNO 5 (JV) | PLAN DE COORDINACIÓN CON LA ACTIVIDAD MUNICIPAL Y LOS EQUIPAMIENTOS ADYACENTES 5 (JV) | MEJORA 1: CANALIZACIONES ADICIONALES 5 | CONTROL DE CALIDAD ADICIONAL 5 | PLAN DE INFORMACIÓN PÚBLICA Y DE GESTIÓN DE INCIDENCIAS 5 (JV) | Q32: definitiva 5% | T32: 45453100; 45313100; 45331210 | U32: PCAP | V32: PPT | W32: Ver | X32: 46310
B33: 46329.792 | C33: =IF(B33="","",INT(B33)-TODAY()) | D33: 669122.06 | E33: 669122.06 | F33: Andalucía | G33: Córdoba | H33: Córdoba | I33: Presidencia del Consejo de Administración de la Empresa Provincial de Aguas de Córdoba S.A. | J33: Obra de Red de Abastecimiento Aldea del Villar (Fuente Palmera). | K33: CC 55/2026 | L33: Abierto | M33: 12 | N33: E1-3 | O33: 0.5 | P33: Ampliación plazo de garantía 10 (JV) | Oferta económica 50 | Oferta técnica 40 (JV) | T33: 45240000 | U33: PCAP | V33: PPT | W33: Ver | X33: 46310
B34: 46329.792 | C34: =IF(B34="","",INT(B34)-TODAY()) | D34: 1071077.5 | E34: 1071077.5 | F34: Andalucía | G34: Almería | H34: Almería | I34: Presidencia de la Autoridad Portuaria de Almería | J34: Obras de Reforma de Pasarelas 4 y 5 en Puerto de Almería | K34: 31/O/A/AL26 | L34: Abierto | M34: 12 | N34: C3-4 | O34: 0.25 | P34: Cuantitativos 75 | Cualitativos 25 (JV) | T34: 45223210; 45223100 | U34: PCAP | V34: PPT | W34: Ver | X34: 46310
B35: 46329.792 | C35: =IF(B35="","",INT(B35)-TODAY()) | D35: 13104057 | E35: 13104057 | F35: Andalucía | G35: Jaén | I35: Pleno del Ayuntamiento de Jaén | J35: Contratación de las obras de reparación de pavimentos de calles del municipio de Jaén tras concatenación de borrascas durante los meses de enero y febrero de 2026, financiadas por la Administración General del Estado, a través del Ministerio de Política Territorial y Memoria Democrática, al amparo del art. 7 del Real Decreto-Ley 5/2026, de 17 de febrero. | K35: 2026000083 | L35: Abierto | M35: 4 | O35: 0.25 | P35: Proceso constructivo 10 (JV) | Precio 55 | Disponibilidad para trabajos nocturnos 10 | Programa de trabajo 15 (JV) | Plazo de garantía 10 | Q35: definitiva 5% | S35: 6 | T35: 45233252; 45111100; 45262300; 45262522 | U35: PCAP | V35: PPT | W35: Ver | X35: 46310
B36: 46329.792 | C36: =IF(B36="","",INT(B36)-TODAY()) | D36: 1565254.7 | E36: 1565254.7 | F36: Andalucía | G36: Almería | H36: Almería | I36: Presidencia de la Autoridad Portuaria de Almería | J36: Obras de reforma de Pasarelas 2 y 3 en Puerto de Almería | K36: 26/O/A/AL26 | L36: Abierto | M36: 6 | N36: C3-4 | O36: 0.25 | P36: Cuantitativos 75 | Cualitativos 25 (JV) | T36: 45223210; 45223100 | U36: PCAP | V36: PPT | W36: Ver | X36: 46310
B37: 46329.999 | C37: =IF(B37="","",INT(B37)-TODAY()) | D37: 564012.4 | E37: 564012.4 | F37: Comunitat Valenciana | H37: Oliva | I37: Concejal de Contratación del Ayuntamiento de Oliva | J37: Mejora de la accesibilidad en espacios públicos y renovación de la red de abastecimiento de agua potable | K37: 15056/2026 | L37: Abierto simplificado | M37: 5 | O37: 0 | P37: Ampliación adicional plazo de garantía 10 | Baja económica en el tipo de licitación 20 | Conjunto de mejoras 70 | Q37: definitiva 5%; complementaria 2% | T37: 45200000 | U37: PCAP | V37: PPT | W37: Ver | X37: 46310
B38: 46329.999 | C38: =IF(B38="","",INT(B38)-TODAY()) | D38: 1106611.6 | E38: 1106611.6 | F38: Andalucía | G38: Sevilla | I38: Alcaldía del Ayuntamiento de Alcalá del Río | J38: Contrato de obras relativo al Proyecto básico y de ejecución de Reforma y Acondicionamiento de la Piscina Municipal y el entorno periférico | K38: P4100500J-2026/000021-PAAS | L38: Abierto simplificado | M38: 16 | N38: J2-2; C3-2; C*-2; J*-2 | O38: 0 | P38: Aspecto Económico (precio) [1] 40 | Mejora 1 Nuevo sistema de Riego para las zonas de césped [2] 20 | Mejora 2 Retirada y renovación del césped [3] 40 | T38: 45212220 | U38: PCAP | V38: PPT | W38: Ver | X38: 46310
B39: 46329.999 | C39: =IF(B39="","",INT(B39)-TODAY()) | D39: 3060580.6 | E39: 3060580.6 | F39: Andalucía | G39: Huelva | I39: Pleno del Ayuntamiento de Punta umbría | J39: Ejecución de las obras para la renovación y mejora de la eficiencia energética de las instalaciones de alumbrado público exterior en el Municipio de Punta Umbría (Huelva) | K39: 5163/2026 | L39: Abierto | M39: 9 | N39: I1-4 | O39: 0.25 | P39: Memoria Técnica 25 (JV) | Reducción de Plazos 20 | Oferta económica 35 | Experiencia Profesional 20 | Q39: definitiva 5% | T39: 45316100; 45315600; 34928500 | U39: PCAP | V39: PPT | W39: Ver | X39: 46310
B40: 46329.999 | C40: =IF(B40="","",INT(B40)-TODAY()) | D40: 2370624.5 | E40: 2844749.4 | F40: Andalucía | G40: Almería | I40: Junta de Gobierno Local del Ayuntamiento de El Ejido | J40: Es objeto de la presente licitación es la contratación de la ejecución del proyecto de obras denominado: Proyecto de construcción de adecuación del complejo deportivo en el núcleo de Almerimar. Fase II, conforme a las especificaciones y características expuestas en el presente pliego y en el proyecto técnico. | K40: 2026 1137 | L40: Abierto | M40: 6 | O40: 0.25 | P40: Proposición económica 75 | Criterios evaluables mediante un juicio de valor 25 (JV) | Q40: provisional 5% | T40: 45200000 | U40: PCAP | V40: PPT | W40: Ver | X40: 46310
...

Sheet Resumen
A1: Licitaciones de obras en plazo · Resumen
A3: Actualizado | B3: 46321.287
A4: Ámbito (códigos NUTS) | B4: ES52, ES61
A5: Rango de presupuesto base sin IVA | B5: entre 500.000,00 € y ∞
A6: Fuentes leídas | B6: 0 fichero(s) mensual(es) + 14 página(s) del feed
A7: Entradas leídas | B7: 6555
A8: Periodo cubierto en esta lectura | B8: 21/10/2026 – 25/10/2026
A9: Licitaciones en la base | B9: 2050
A10: En plazo | B10: =COUNTA('En plazo'!$J$2:$J$102)
A11: Importe total en plazo | B11: =SUM('En plazo'!$D$2:$D$102)
A12: Nuevas desde la ejecución anterior | B12: =COUNTIF('En plazo'!$A$2:$A$102,"SÍ")
A13: Con cambios registrados | B13: =COUNTIF('En plazo'!$Y$2:$Y$102,"?*")
A14: Vencen en 7 días o menos | B14: =COUNTIFS('En plazo'!$C$2:$C$102,">=0",'En plazo'!$C$2:$C$102,"<=7")
A16: Por comunidad y provincia
A17: Comunidad | B17: Provincia | C17: Nº en plazo | D17: Importe | E17: Nuevas | F17: Vencen ≤ 7 días
A18: Andalucía | B18: Almería | C18: =COUNTIFS('En plazo'!$F$2:$F$102,"Andalucía",'En plazo'!$G$2:$G$102,"Almería") | D18: =SUMIFS('En plazo'!$D$2:$D$102,'En plazo'!$F$2:$F$102,"Andalucía",'En plazo'!$G$2:$G$102,"Almería") | E18: =COUNTIFS('En plazo'!$F$2:$F$102,"Andalucía",'En plazo'!$G$2:$G$102,"Almería",'En plazo'!$A$2:$A$102,"SÍ") | F18: =COUNTIFS('En plazo'!$F$2:$F$102,"Andalucía",'En plazo'!$G$2:$G$102,"Almería",'En plazo'!$C$2:$C$102,">=0",'En plazo'!$C$2:$C$102,"<=7")
A19: Andalucía | B19: Cádiz | C19: =COUNTIFS('En plazo'!$F$2:$F$102,"Andalucía",'En plazo'!$G$2:$G$102,"Cádiz") | D19: =SUMIFS('En plazo'!$D$2:$D$102,'En plazo'!$F$2:$F$102,"Andalucía",'En plazo'!$G$2:$G$102,"Cádiz") | E19: =COUNTIFS('En plazo'!$F$2:$F$102,"Andalucía",'En plazo'!$G$2:$G$102,"Cádiz",'En plazo'!$A$2:$A$102,"SÍ") | F19: =COUNTIFS('En plazo'!$F$2:$F$102,"Andalucía",'En plazo'!$G$2:$G$102,"Cádiz",'En plazo'!$C$2:$C$102,">=0",'En plazo'!$C$2:$C$102,"<=7")
A20: Andalucía | B20: Córdoba | C20: =COUNTIFS('En plazo'!$F$2:$F$102,"Andalucía",'En plazo'!$G$2:$G$102,"Córdoba") | D20: =SUMIFS('En plazo'!$D$2:$D$102,'En plazo'!$F$2:$F$102,"Andalucía",'En plazo'!$G$2:$G$102,"Córdoba") | E20: =COUNTIFS('En plazo'!$F$2:$F$102,"Andalucía",'En plazo'!$G$2:$G$102,"Córdoba",'En plazo'!$A$2:$A$102,"SÍ") | F20: =COUNTIFS('En plazo'!$F$2:$F$102,"Andalucía",'En plazo'!$G$2:$G$102,"Córdoba",'En plazo'!$C$2:$C$102,">=0",'En plazo'!$C$2:$C$102,"<=7")
A21: Andalucía | B21: Granada | C21: =COUNTIFS('En plazo'!$F$2:$F$102,"Andalucía",'En plazo'!$G$2:$G$102,"Granada") | D21: =SUMIFS('En plazo'!$D$2:$D$102,'En plazo'!$F$2:$F$102,"Andalucía",'En plazo'!$G$2:$G$102,"Granada") | E21: =COUNTIFS('En plazo'!$F$2:$F$102,"Andalucía",'En plazo'!$G$2:$G$102,"Granada",'En plazo'!$A$2:$A$102,"SÍ") | F21: =COUNTIFS('En plazo'!$F$2:$F$102,"Andalucía",'En plazo'!$G$2:$G$102,"Granada",'En plazo'!$C$2:$C$102,">=0",'En plazo'!$C$2:$C$102,"<=7")
A22: Andalucía | B22: Huelva | C22: =COUNTIFS('En plazo'!$F$2:$F$102,"Andalucía",'En plazo'!$G$2:$G$102,"Huelva") | D22: =SUMIFS('En plazo'!$D$2:$D$102,'En plazo'!$F$2:$F$102,"Andalucía",'En plazo'!$G$2:$G$102,"Huelva") | E22: =COUNTIFS('En plazo'!$F$2:$F$102,"Andalucía",'En plazo'!$G$2:$G$102,"Huelva",'En plazo'!$A$2:$A$102,"SÍ") | F22: =COUNTIFS('En plazo'!$F$2:$F$102,"Andalucía",'En plazo'!$G$2:$G$102,"Huelva",'En plazo'!$C$2:$C$102,">=0",'En plazo'!$C$2:$C$102,"<=7")
A23: Andalucía | B23: Jaén | C23: =COUNTIFS('En plazo'!$F$2:$F$102,"Andalucía",'En plazo'!$G$2:$G$102,"Jaén") | D23: =SUMIFS('En plazo'!$D$2:$D$102,'En plazo'!$F$2:$F$102,"Andalucía",'En plazo'!$G$2:$G$102,"Jaén") | E23: =COUNTIFS('En plazo'!$F$2:$F$102,"Andalucía",'En plazo'!$G$2:$G$102,"Jaén",'En plazo'!$A$2:$A$102,"SÍ") | F23: =COUNTIFS('En plazo'!$F$2:$F$102,"Andalucía",'En plazo'!$G$2:$G$102,"Jaén",'En plazo'!$C$2:$C$102,">=0",'En plazo'!$C$2:$C$102,"<=7")
A24: Andalucía | B24: Málaga | C24: =COUNTIFS('En plazo'!$F$2:$F$102,"Andalucía",'En plazo'!$G$2:$G$102,"Málaga") | D24: =SUMIFS('En plazo'!$D$2:$D$102,'En plazo'!$F$2:$F$102,"Andalucía",'En plazo'!$G$2:$G$102,"Málaga") | E24: =COUNTIFS('En plazo'!$F$2:$F$102,"Andalucía",'En plazo'!$G$2:$G$102,"Málaga",'En plazo'!$A$2:$A$102,"SÍ") | F24: =COUNTIFS('En plazo'!$F$2:$F$102,"Andalucía",'En plazo'!$G$2:$G$102,"Málaga",'En plazo'!$C$2:$C$102,">=0",'En plazo'!$C$2:$C$102,"<=7")
A25: Andalucía | B25: Sevilla | C25: =COUNTIFS('En plazo'!$F$2:$F$102,"Andalucía",'En plazo'!$G$2:$G$102,"Sevilla") | D25: =SUMIFS('En plazo'!$D$2:$D$102,'En plazo'!$F$2:$F$102,"Andalucía",'En plazo'!$G$2:$G$102,"Sevilla") | E25: =COUNTIFS('En plazo'!$F$2:$F$102,"Andalucía",'En plazo'!$G$2:$G$102,"Sevilla",'En plazo'!$A$2:$A$102,"SÍ") | F25: =COUNTIFS('En plazo'!$F$2:$F$102,"Andalucía",'En plazo'!$G$2:$G$102,"Sevilla",'En plazo'!$C$2:$C$102,">=0",'En plazo'!$C$2:$C$102,"<=7")
A26: Comunitat Valenciana | B26: (sin provincia) | C26: =COUNTIFS('En plazo'!$F$2:$F$102,"Comunitat Valenciana",'En plazo'!$G$2:$G$102,"") | D26: =SUMIFS('En plazo'!$D$2:$D$102,'En plazo'!$F$2:$F$102,"Comunitat Valenciana",'En plazo'!$G$2:$G$102,"") | E26: =COUNTIFS('En plazo'!$F$2:$F$102,"Comunitat Valenciana",'En plazo'!$G$2:$G$102,"",'En plazo'!$A$2:$A$102,"SÍ") | F26: =COUNTIFS('En plazo'!$F$2:$F$102,"Comunitat Valenciana",'En plazo'!$G$2:$G$102,"",'En plazo'!$C$2:$C$102,">=0",'En plazo'!$C$2:$C$102,"<=7")
A27: Comunitat Valenciana | B27: Alicante | C27: =COUNTIFS('En plazo'!$F$2:$F$102,"Comunitat Valenciana",'En plazo'!$G$2:$G$102,"Alicante") | D27: =SUMIFS('En plazo'!$D$2:$D$102,'En plazo'!$F$2:$F$102,"Comunitat Valenciana",'En plazo'!$G$2:$G$102,"Alicante") | E27: =COUNTIFS('En plazo'!$F$2:$F$102,"Comunitat Valenciana",'En plazo'!$G$2:$G$102,"Alicante",'En plazo'!$A$2:$A$102,"SÍ") | F27: =COUNTIFS('En plazo'!$F$2:$F$102,"Comunitat Valenciana",'En plazo'!$G$2:$G$102,"Alicante",'En plazo'!$C$2:$C$102,">=0",'En plazo'!$C$2:$C$102,"<=7")
A28: Comunitat Valenciana | B28: Castellón | C28: =COUNTIFS('En plazo'!$F$2:$F$102,"Comunitat Valenciana",'En plazo'!$G$2:$G$102,"Castellón") | D28: =SUMIFS('En plazo'!$D$2:$D$102,'En plazo'!$F$2:$F$102,"Comunitat Valenciana",'En plazo'!$G$2:$G$102,"Castellón") | E28: =COUNTIFS('En plazo'!$F$2:$F$102,"Comunitat Valenciana",'En plazo'!$G$2:$G$102,"Castellón",'En plazo'!$A$2:$A$102,"SÍ") | F28: =COUNTIFS('En plazo'!$F$2:$F$102,"Comunitat Valenciana",'En plazo'!$G$2:$G$102,"Castellón",'En plazo'!$C$2:$C$102,">=0",'En plazo'!$C$2:$C$102,"<=7")
A29: Comunitat Valenciana | B29: Valencia | C29: =COUNTIFS('En plazo'!$F$2:$F$102,"Comunitat Valenciana",'En plazo'!$G$2:$G$102,"Valencia") | D29: =SUMIFS('En plazo'!$D$2:$D$102,'En plazo'!$F$2:$F$102,"Comunitat Valenciana",'En plazo'!$G$2:$G$102,"Valencia") | E29: =COUNTIFS('En plazo'!$F$2:$F$102,"Comunitat Valenciana",'En plazo'!$G$2:$G$102,"Valencia",'En plazo'!$A$2:$A$102,"SÍ") | F29: =COUNTIFS('En plazo'!$F$2:$F$102,"Comunitat Valenciana",'En plazo'!$G$2:$G$102,"Valencia",'En plazo'!$C$2:$C$102,">=0",'En plazo'!$C$2:$C$102,"<=7")
A30: Total | C30: =SUM(C18:C29) | D30: =SUM(D18:D29) | E30: =SUM(E18:E29) | F30: =SUM(F18:F29)
A32: Fuente: Plataforma de Contratación del Sector Público (feed ATOM licitacionesPerfilesContratanteCompleto3) y ficheros mensuales de datos abiertos del Ministerio de Hacienda.
A33: Los días restantes y los vencimientos se recalculan con la fecha del día al abrir el libro.
A34: Plazo de ejecución en meses: los plazos en días se dividen entre 30 y los de años se multiplican por 12.
A35: Este libro se regenera en cada ejecución: las anotaciones que se hagan en él se pierden. Para el seguimiento, copiar las filas al libro de preselección.

Sheet Histórico
A1: Estado | B1: Fecha límite | C1: Presupuesto base sin IVA | D1: Valor estimado | E1: Comunidad | F1: Provincia | G1: Municipio | H1: Órgano de contratación | I1: Objeto | J1: Expediente | K1: Procedimiento | L1: Plazo de ejecución (meses) | M1: Clasificación exigida | N1: Juicio de valor | O1: Nº lotes | P1: CPV | Q1: Ficha PLACSP | R1: PCAP | S1: Primera detección | T1: Última actualización en PLACSP | U1: Cambios
A2: En plazo | B2: 46335.583 | C2: 65084.97 | D2: 65084.97 | E2: Andalucía | F2: Huelva | G2: santa bárbara de casa | H2: Alcaldía del Ayuntamiento de Santa Bárbara de Casa | I2: contrato de obras de urbanización mediante obras ordinarias | J2: 480.1/2026 | K2: Abierto simplificado | L2: 3 | N2: 0 | P2: 45233252 | Q2: Ver | S2: 46321 | T2: 46320.807
A3: En plazo | B3: 46351.542 | C3: 15485879 | D3: 20131642 | E3: Comunitat Valenciana | F3: Valencia | G3: Valencia | H3: Consejo de Administración de la Autoridad Portuaria de Valencia | I3: Construcción de nueva subestación transformadora de 132/20 kV tipo GIS de interior con dos transformadores 132/20 kV, 55 MVA-ST. Autoridad Portuaria de Valencia 2 | J3: EC26-C02-02310 | K3: Abierto | L3: 20 | M3: I4-4 | N3: 0.49 | P3: 45232220 | Q3: Ver | R3: PCAP | S3: 46321 | T3: 46320.436
A4: Resuelta | B4: 46220.999 | C4: 5985824.8 | D4: 5985824.8 | E4: Andalucía | F4: Málaga | H4: Pleno del Ayuntamiento de Alhaurín de la Torre | I4: Obras para la construcción del aparcamiento subterráneo disuasorio en la Avenida Isaac Peral y la reurbanización y peatonalización parcial de la Avenida Isaac Peral en el T.M. Alhaurín de la Torre. | J4: 2026 CONT-00019 | K4: Abierto | L4: 30 | M4: C2-4 | N4: 0 | P4: 45200000; 45340000; 45261000; 45440000; 45320000; 45213316; 45330000; 45420000 | Q4: Ver | R4: PCAP | S4: 46321 | T4: 46320.31
A5: Resuelta | B5: 46294.999 | C5: 29981.19 | D5: 32979.31 | E5: Comunitat Valenciana | F5: Castellón | G5: Castelló de la Plana | H5: Dirección Económica del Consorcio Hospitalario Provincial de Castellón | I5: CMAYOR/2026/HPC00/0737 OBRAS de renovación y adaptación de tres aseos existentes en la planta baja del Consorcio Hospitalario Provincial Universitario de Castellón, ubicados en los bloques A (Consultas Externas), C (Área de Rehabilitación) y D (Área de Oncología), incorporando en cada uno de ellos equipamiento higiénico específico para personas ostomizadas | J5: CMAYOR/2026/HPC00/0737 | K5: Abierto simplificado | L5: 2 | N5: 0 | P5: 45000000; 45215140 | Q5: Ver | R5: PCAP | S5: 46311 | T5: 46319.802 | U5: 2026-10-26: estado ADJ → RES
A6: En plazo | B6: 46335.999 | C6: 41322.31 | D6: 41322.31 | E6: Andalucía | F6: Sevilla | H6: Alcaldia del Ayuntamiento de Marinaleda | I6: Reparación de Caminos Rurales (Línea de Subvenciones Borrasca NELSON) | J6: P4106100C-2026/000108-PAAB | K6: Abierto simplificado | L6: 3 | N6: 0 | P6: 45233142 | Q6: Ver | R6: PCAP | S6: 46321 | T6: 46319.539
A7: En plazo | B7: 46335.999 | C7: 45409.09 | D7: 45409.09 | E7: Andalucía | F7: Sevilla | H7: Alcaldia del Ayuntamiento de Marinaleda | I7: Mejora de Caminos Rurales de Marinaleda (Sevilla) | J7: P4106100C-2026/000107-PAAB | K7: Abierto simplificado | L7: 3 | N7: 0 | P7: 45233142 | Q7: Ver | R7: PCAP | S7: 46321 | T7: 46319.536
A8: En plazo | B8: 46332.542 | C8: 55300.65 | D8: 55300.65 | E8: Andalucía | F8: Huelva | G8: SANTA BARBARA DE CASA | H8: Alcaldía del Ayuntamiento de Santa Bárbara de Casa | I8: contrato de obras de mejora de la calle Noria en Santa Bárbara de Casa | J8: 480/2026 | K8: Abierto simplificado | L8: 3 | N8: 0 | P8: 45233252 | Q8: Ver | S8: 46317 | T8: 46319.525
A9: En plazo | B9: 46335.999 | C9: 27389.04 | D9: 27389.04 | E9: Andalucía | F9: Huelva | G9: PAYMOGO | H9: Alcaldía del Ayuntamiento de Paymogo | I9: Constituye el objeto del contrato la ejecución de las obras de reparación del firme del Camino de Las Peñuelas, de Paymogo (Huelva), de titularidad municipal, con referencia catastral 21057A009090040000LO | J9: 493/2026 | K9: Abierto simplificado | L9: 1 | N9: 0 | P9: 45233160 | Q9: Ver | R9: PCAP | S9: 46321 | T9: 46318.842
A10: En plazo | B10: 46338.999 | C10: 175462.98 | D10: 175462.98 | E10: Comunitat Valenciana | F10: Valencia | H10: Alcaldía del Ayuntamiento de Moixent | I10: Consolidación de la torre sur del Castillo de Moixent, Fase I | J10: 1615/2026 | K10: Abierto simplificado | L10: 4 | N10: 0.12 | P10: 45212314; 45454100; 45262512; 45212350 | Q10: Ver | R10: PCAP | S10: 46321 | T10: 46318.72
A11: En plazo | B11: 46338.999 | C11: 328657.46 | D11: 328657.46 | E11: Andalucía | F11: Sevilla | G11: Écija | H11: Junta de Gobierno del Ayuntamiento de Ecija | I11: Obras Rehabilitación y Puesta en uso de Salas junto a Patio de las Yeguas del Palacio Marqueses de Peñaflor, por procedimiento abierto simplificado,tramitación ordinaria, financiado con cargo al 2% Cultural del Ministerio deTransportes, Movilidad y Agenda Urbana para conservación o enriquecimiento de bienes inmuebles del Patrimonio Histórico Español. | J11: 16242/2025 | K11: Abierto simplificado | L11: 6 | N11: 0 | P11: 45212350 | Q11: Ver | R11: PCAP | S11: 46321 | T11: 46318.717
A12: En plazo | B12: 46350.542 | C12: 22148579 | D12: 26338629 | E12: Andalucía | F12: Málaga | H12: Junta de Gobierno del Ayuntamiento de Málaga | I12: Redacción del proyecto constructivo y ejecución de las obras del soterramiento de la Avenida de Valle-Inclán en la intersección con el Camino de Suárez, la Calle Martínez de la Rosa y el acceso a las barriadas de Carlinda, La Corta y San Alberto, en la ciudad de Málaga | J12: 31/26 | K12: Abierto | L12: 31 | M12: B2-6; G6-3 | N12: 0.49 | P12: 45221000; 71300000 | Q12: Ver | R12: PCAP | S12: 46321 | T12: 46318.681
A13: Resuelta | B13: 46216.999 | C13: 156579.12 | D13: 156579.12 | E13: Comunitat Valenciana | F13: Valencia | H13: Junta de Gobierno del Ayuntamiento de Alboraya | I13: Obras de reforma del antiguo polideportivo de Alboraya | J13: 704/2026 | K13: Abierto simplificado | L13: 4 | N13: 0 | P13: 45212290 | Q13: Ver | R13: PCAP | S13: 46321 | T13: 46318.656
A14: Adjudicada | B14: 46259.999 | C14: 111113.32 | D14: 111113.32 | E14: Andalucía | F14: Córdoba | H14: Alcaldía del Ayuntamiento de Rute | I14: Ejecución del Proyecto de Arreglo de la Pista Deportiva en CEIP Ruperto Fernandez Tenllado (Córdoba) | J14: 2830_26 OBRAS PISTA POLID CEIP RUPERTO FDEZ | K14: Abierto simplificado | L14: 2.5 | N14: 0 | P14: 45212220; 45200000 | Q14: Ver | R14: PCAP | S14: 46310 | T14: 46318.63 | U14: 2026-10-26: estado EV → ADJ
A15: Adjudicada | B15: 46295.999 | C15: 165448.79 | D15: 165448.79 | E15: Andalucía | F15: Córdoba | G15: ALDEA DE NACIMIENTO DE ZAMBRA | H15: Alcaldía del Ayuntamiento de Rute | I15: Ejecución del Proyecto de Reparación y Adecentamiento de la pista polideportiva de la Aldea de Nacimiento de Zambra de Rute | J15: 3862_26 OBRAS PISTAS NAC ZAMBRA | K15: Abierto simplificado | L15: 4 | N15: 0 | P15: 45212220; 45212290; 45212213 | Q15: Ver | R15: PCAP | S15: 46310 | T15: 46318.625 | U15: 2026-10-26: estado EV → ADJ
A16: En plazo | B16: 46346.999 | C16: 8318780.9 | D16: 8318780.9 | E16: Andalucía | F16: Sevilla | H16: Junta de Gobierno del Ayuntamiento de Carmona | I16: Obras para la ejecución del complejo de la música y el patrimonio en los antiguos mataderos de Carmona y la adecuación de sus entornos. | J16: EXP 25-173-22 | K16: Abierto | L16: 20 | M16: C*-5 | N16: 0.45 | P16: 45000000; 45212300; 45213230; 45112700; 45212321; 45454100 | Q16: Ver | R16: PCAP | S16: 46311 | T16: 46318.625
A17: En plazo | B17: 46337.999 | C17: 206393.65 | D17: 206393.65 | E17: Comunitat Valenciana | F17: Valencia | H17: Alcaldía del Ayuntamiento de Alberic | I17: El objeto del contrato es la ejecución de las obras destinadas a la Rehabilitación y adecuación de la antigua cisterna del Palacio Señorial de Alberic (usada como refugio antiaéreo en el transcurso de la Guerra Civil) como espacio de memoria democrática. | J17: 3019777K nueva licitación | K17: Abierto simplificado | L17: 4 | N17: 0 | P17: 45212350 | Q17: Ver | R17: PCAP | S17: 46321 | T17: 46318.621
A18: En plazo | B18: 46377.583 | C18: 21241200 | D18: 25355520 | E18: Comunitat Valenciana | F18: Valencia | H18: Presidencia de la Entidad Valenciana de Vivienda y Suelo | I18: Redacción del proyecto, ejecución de las obras y dirección facultativa para la construcción por procedimientos industrializados promovidas por la Entidad Valenciana de Vivienda y Suelo, en Silla y Carcaixent. | J18: CMAYOR/2026/EVHA0/0014 | K18: Abierto | L18: 12 | N18: 0.49 | O18: 4 | P18: 45211100; 71000000 | Q18: Ver | R18: PCAP | S18: 46314 | T18: 46318.613 | U18: 2026-10-20: plazo 2026-11-19 14:00 → 2026-12-21 14:00
A19: Adjudicada | B19: 46251.999 | C19: 396270 | D19: 396270 | E19: Comunitat Valenciana | F19: Valencia | G19: Vallada | H19: Alcaldía del Ayuntamiento de Vallada | I19: Reurbanización calles San Ramón, Santa Teresa y San lorenzo con realización de red separativa de pluviales, renovación de red de saneamiento y de agua potable, y sustitución de pavimentos | J19: 2685373K1 | K19: Abierto simplificado | L19: 5 | N19: 0 | P19: 45231300; 45232130; 45233252; 45232410 | Q19: Ver | R19: PCAP | S19: 46311 | T19: 46318.61 | U19: 2026-10-26: estado EV → ADJ
A20: Pendiente de adjudicación | B20: 46195.999 | C20: 3063829.2 | D20: 3063829.2 | E20: Andalucía | F20: Sevilla | H20: Presidencia de la Diputación Provincial de Sevilla | I20: Rehabilitación del salón de actos de los centros sociales de miraflores | J20: 2025/000942-PAA | K20: Abierto | L20: 12 | M20: C6-5 | N20: 0 | P20: 45000000 | Q20: Ver | R20: PCAP | S20: 46321 | T20: 46318.609
A21: Pendiente de adjudicación | B21: 46314.999 | C21: 83128.44 | D21: 83128.44 | E21: Andalucía | F21: Málaga | G21: Málaga | H21: Subdirección General de Administración Financiera y Patrimonio de la Administración General del Estado en el Territorio | I21: Ejecución de las obras de Sustitución de las luminarias a tecnología LED en la instalación de iluminación interior de la Oficina de Extranjería en Málaga situada en la Calle Mauricio Moro Pareto nº 13 (Código Postal 29006 de Málaga) | J21: 202686026070 | K21: Abierto simplificado | L21: 1 | N21: 0 | P21: 45316000 | Q21: Ver | R21: PCAP | S21: 46321 | T21: 46318.607
A22: En plazo | B22: 46339.999 | C22: 76859.5 | D22: 76859.5 | E22: Andalucía | F22: Málaga | G22: Alameda | H22: Alcaldía del Ayuntamiento de Alameda | I22: Constituye el objeto del presente pliego la contratación para la ejecución de las obras de Proyecto de instalación solar fotovoltaica para autoconsumo de 55 kW para sondeo en El Camorrillo, Alameda,Málaga | J22: 1866/2026 | K22: Abierto simplificado | L22: 4 | N22: 0 | P22: 45310000; 09332000; 09300000; 09331200 | Q22: Ver | R22: PCAP | S22: 46321 | T22: 46318.606
A23: En plazo | B23: 46342.999 | C23: 166994.64 | D23: 217093.03 | E23: Comunitat Valenciana | F23: Valencia | H23: Consorcio Hospital General Universitario de Valencia | I23: Contrato de obras, responsable con el medioambiente, para la reforma y mejora de la eficiencia energética del centro de atención de urgencias (CAU) 24 horas en el CS Torrent I. | J23: CMAYOR/2027/HGUV0/0141 | K23: Abierto simplificado | L23: 4 | N23: 0.25 | P23: 45215100 | Q23: Ver | R23: PCAP | S23: 46321 | T23: 46318.604
A24: Resuelta | B24: 46021.583 | C24: 172998.93 | D24: 172998.93 | E24: Andalucía | F24: Cádiz | G24: La Línea de La Concepción | H24: Alcaldía del Ayuntamiento de la Línea de la Concepción | I24: contrato de obra de “Proyecto de ejecución de pistas de deporte playa en Ciudad Deportiva de La Línea de la Concepción | J24: 118/25 | K24: Abierto simplificado | L24: 3 | N24: 0.25 | P24: 45212200; 45212000; 45210000; 45212210; 45000000; 45200000 | Q24: Ver | R24: PCAP | S24: 46321 | T24: 46318.604
A25: Pendiente de adjudicación | B25: 46232.562 | C25: 1812017.5 | D25: 1812017.5 | E25: Andalucía | F25: Cádiz | H25: Junta de Gobierno del Ayuntamiento de Chiclana de la Frontera | I25: Obras de transformación de carretera de Pago del Humo en vía urbana. | J25: 31/2026 | K25: Abierto simplificado | L25: 12 | M25: G6-4 | N25: 0.25 | P25: 45233140 | Q25: Ver | R25: PCAP | S25: 46311 | T25: 46318.602
A26: En plazo | B26: 46336.999 | C26: 132467.55 | D26: 132467.55 | E26: Comunitat Valenciana | F26: Valencia | H26: Servicio de Emergencias Sanitarias de la Comunitat Valenciana. Dirección Económica-Gerencia | I26: Dirección de obra y obra para la adecuación y habilitación de las instalaciones e infraestructuras sitas en la localidad de Sueca del Servicio de Emergencias Sanitarias de la Comunitat Valenciana. | J26: CNMY 1656/2026 | K26: Abierto simplificado | L26: 3.3 | N26: 0 | O26: 2 | P26: 45215100; 71240000; 71317210 | Q26: Ver | R26: PCAP | S26: 46310 | T26: 46318.601 | U26: 2026-10-22: plazo 2026-10-21 23:59 → 2026-11-10 23:59
A27: En plazo | B27: 46336.999 | C27: 358728.57 | D27: 358728.57 | E27: Andalucía | F27: Málaga | H27: Gerente de la Gerencia Municipal de Urbanismo del Ayuntamiento de Málaga | I27: Proyecto de remodelación de la plaza de la Biznaga en Cruz de Humilladero. Actuación cofinanciada por la Unión Europea a través del Fondo Europeo de Desarrollo Regional (FEDER), Programa Plurirregional de España (POPE) (2021-2027) | J27: 2026000065/GMU/OBR/ABR_SMPL | K27: Abierto simplificado | L27: 4 | N27: 0 | P27: 45233200; 45112710 | Q27: Ver | R27: PCAP | S27: 46317 | T27: 46318.601
A28: En plazo | B28: 46342.999 | C28: 3636363.6 | D28: 3636363.6 | E28: Andalucía | F28: Almería | H28: Junta de Gobierno de la Diputación Provincial de Almería | I28: Gran Eco-bulevard Vera - Palomares. Este Proyecto Podrá Ser Cofinanciado Por La Unión Europea A Través Del Fondo Europeo De Desarrollo Regional (feder) En El Marco Del Programa Plurirregional De Españ 9PAI-LEVANTE30 | J28: 2026/D31000/006-002/00004 | K28: Abierto | L28: 12.2 | M28: I1-4; G6-4 | N28: 0.25 | P28: 45111291 | Q28: Ver | R28: PCAP | S28: 46317 | T28: 46318.6
A29: Pendiente de adjudicación | B29: 46296.542 | C29: 450480.72 | D29: 450480.72 | E29: Comunitat Valenciana | F29: Alicante | G29: Monforte del Cid | H29: Junta de Gobierno del Ayuntamiento de Monforte del Cid | I29: La ejecución de las obras definidas en el Proyecto Básico y de Mejoras de Ejecución denominado Acondicionamiento de Café-Bar del Polideportivo Municipal y espacio libre anexo | J29: 3022/2026 Acondicionamiento cafe bar polideportivo | K29: Abierto simplificado | L29: 8 | N29: 0 | P29: 45000000; 45453100; 45210000; 45300000 | Q29: Ver | R29: PCAP | S29: 46310 | T29: 46318.599
A30: Adjudicada | B30: 46275.999 | C30: 173616.64 | D30: 173616.64 | E30: Andalucía | F30: Málaga | G30: ALAMEDA | H30: Alcaldía del Ayuntamiento de Alameda | I30: Obras de pavimentado de calle almendros, prolongación Avenida la Libertad y prolongación Blas Infante en el núcleo urbano de Alameda (Málaga), consistentes en la mejora del estado del firme y pavimentación sobre la calzada existente | J30: 1909/2026 | K30: Abierto simplificado | L30: 1 | N30: 0 | P30: 45233252 | Q30: Ver | R30: PCAP | S30: 46321 | T30: 46318.598
A31: Adjudicada | B31: 46215.999 | C31: 132231.4 | D31: 132231.4 | E31: Andalucía | F31: Málaga | G31: ALAMEDA | H31: Alcaldía del Ayuntamiento de Alameda | I31: Renovación del pavimento del pabellón de deportes José Francisco Torres Narbona, del Ayuntamiento de Alameda, a fin de mejorar el pavimento para la práctica deportiva, especialmente en lo concerniente a la práctica de futbol sala, baloncesto y balonmano, conforme a las especificaciones recogidas en el Pliego de Prescripciones Técnicas y el PCAP | J31: 1478/2026 | K31: Abierto simplificado | L31: 1 | N31: 0 | P31: 45212600 | Q31: Ver | R31: PCAP | S31: 46321 | T31: 46318.598
A32: Adjudicada | B32: 46300.625 | C32: 245175.69 | D32: 245175.69 | E32: Andalucía | F32: Cádiz | H32: Delegación Especial del Estado en el Consorcio de la Zona Franca de Cádiz | I32: Obras necesarias para la ejecución del proyecto de Reparacion de las zonas A-1, A-2, B-1, B-2, C-1, C-2 de la cubierta de la nave 1 del Recinto Interior de la Zona Franca de Cádiz. | J32: CO-0205-2026-00-A | K32: Abierto simplificado | L32: 3.5 | N32: 0.25 | P32: 45261420; 45261910 | Q32: Ver | R32: PCAP | S32: 46310 | T32: 46318.596 | U32: 2026-10-26: estado EV → ADJ
A33: En plazo | B33: 46323.999 | C33: 82639.55 | D33: 82639.55 | E33: Andalucía | F33: Jaén | G33: TORREPEROGIL | H33: Alcaldía del Ayuntamiento de Torreperogil | I33: Recuperación de Muralla histórica y de la cerca del Antiguo Cementerio en calle Perogil, en el municipio de Torreperogil. | J33: 2266/2026 | K33: Abierto simplificado | L33: 5 | N33: 0.2 | P33: 45454100 | Q33: Ver | R33: PCAP | S33: 46310 | T33: 46318.594
A34: Pendiente de adjudicación | B34: 46279.542 | C34: 935351.01 | D34: 1028886.1 | E34: Comunitat Valenciana | F34: Valencia | H34: Presidencia de la Diputación Provincial de Valencia | I34: Ac-631/O. Obras de continuidad y accesibilidad del itinerario ciclo peatonal en la carretera CV-649 entre Vallada y la estación de ferrocarril (TM de Vallada) | J34: 1696/26/CAR | K34: Abierto | L34: 8 | M34: G4-4 | N34: 0.34 | P34: 45233120; 45233162 | Q34: Ver | R34: PCAP | S34: 46317 | T34: 46318.593
A35: Resuelta | B35: 44568.999 | C35: 137452.34 | D35: 137452.34 | E35: Comunitat Valenciana | F35: Valencia | H35: Concejalía Delegada de Contratación del Ajuntament de València | I35: Contrato de obras para la ejecución del proyecto denominado “Rebaje de aceras en pasos de peatones, acondicionamientos de baldosas y paso de peatones sobreelevado en Benimàmet (València)”.- | J35: 04101/2021/257-O | K35: Abierto simplificado | L35: 3 | N35: 0 | P35: 45233251 | Q35: Ver | R35: PCAP | S35: 46321 | T35: 46318.592
A36: Pendiente de adjudicación | B36: 46316.999 | C36: 330257.67 | D36: 330257.67 | E36: Andalucía | F36: Málaga | G36: Cuevas del Becerro | H36: Alcaldía del Ayuntamiento de Cuevas del Becerro | I36: Remodelación completa de la tubería de abastecimiento general que parte desde las inmediaciones del depósito regulador y discurre por la continuación del paseo del Castillejo y la avenida La Fuentezuela, la remodelación completa de dicha avenida y la instalación de un grupo de presión para resolver el proble-ma de baja presión en la zona. | J36: 200/2026 | K36: Abierto simplificado | L36: 6 | N36: 0.1 | P36: 45230000; 45231100; 45233260; 45233140 | Q36: Ver | R36: PCAP | S36: 46321 | T36: 46318.59
A37: En plazo | B37: 46338.999 | C37: 67298.88 | D37: 67298.88 | E37: Andalucía | F37: Almería | H37: Junta de Gobierno de la Diputación Provincial de Almería | I37: Instalación De Sistema De Abastecimiento De Agua Contra Incendios En Residencia Asistida De Mayores. Fase 1, Unidad 14 Y Unidad 10-12. 6PGM2026 | J37: 2026/D31000/006-013/00066 | K37: Abierto simplificado | L37: 3 | N37: 0.25 | P37: 45343200 | Q37: Ver | R37: PCAP | S37: 46321 | T37: 46318.59
A38: Adjudicada | B38: 46232.999 | C38: 666460.78 | D38: 666460.78 | E38: Comunitat Valenciana | F38: Alicante | H38: Junta de Gobierno del Ayuntamiento de Elche | I38: Obras de adaptación viaria en puntos conflictivos de tráfico en el término municipal de Elche. | J38: OBR/ABR_SMPL/2026000107 | K38: Abierto simplificado | L38: 6 | M38: G4-3 | N38: 0.2 | P38: 45233120 | Q38: Ver | R38: PCAP | S38: 46311 | T38: 46318.589 | U38: 2026-10-26: estado EV → ADJ
A39: Pendiente de adjudicación | B39: 46283.833 | C39: 533572.55 | D39: 533572.55 | E39: Andalucía | F39: Granada | G39: Atarfe (Granada) | H39: Dirección Gerente de Aguas Vega Sierra Elvira, S.A. | I39: Renovación de redes de calle jaén y calle marbella Maracena (Granada) | J39: Obras 13/2026 | K39: Abierto | L39: 6 | N39: 0.4 | P39: 45200000; 45231100; 45232100; 45220000; 44160000 | Q39: Ver | R39: PCAP | S39: 46315 | T39: 46318.588
A40: En plazo | B40: 46338.999 | C40: 983261.73 | D40: 983261.73 | E40: Comunitat Valenciana | F40: Alicante | H40: Junta de Gobierno del Ayuntamiento de Aspe | I40: Contrato Administrativo Obras rehabilitación de edificio de viviendas de calle Azorin y urbanizacion anexa en Aspe , Alicante conforme proyecto redactado por UTE PLAN A3 ARQUITECTURA E INGENIERIA, AKTUA MANAGEMENT Y CARMEN TORRES PEREZ | J40: 2026/46-GUACON | K40: Abierto simplificado | L40: 10 | N40: 0 | P40: 45000000 | Q40: Ver | R40: PCAP | S40: 46321 | T40: 46318.587
...
